<?xml version="1.0" encoding="utf-8" standalone="yes"?>
<rss version="2.0" xmlns:atom="http://www.w3.org/2005/Atom">
  <channel>
    <title>django on Machine Code Never Lies</title>
    <link>https://vilisimo.com/categories/django/</link>
    <description>Recent content in django on Machine Code Never Lies</description>
    <generator>Hugo -- gohugo.io</generator>
    <language>en-us</language>
    <lastBuildDate>Sat, 13 Aug 2022 11:37:56 +0300</lastBuildDate><atom:link href="https://vilisimo.com/categories/django/index.xml" rel="self" type="application/rss+xml" />
    <item>
      <title>File System Permissions in Dockerfile</title>
      <link>https://vilisimo.com/blog/file-system-permissions-in-dockerfile/</link>
      <pubDate>Sat, 13 Aug 2022 11:37:56 +0300</pubDate>
      
      <guid>https://vilisimo.com/blog/file-system-permissions-in-dockerfile/</guid>
      <description>Few days ago I was playing with a Django application, trying to containerize it. Everything was going smoothly until I tried to run collectstatic in Dockerfile. Attempting to do so threw the following error:
Traceback (most recent call last): File &amp;#34;/home/project/app/manage.py&amp;#34;, line 33, in &amp;lt;module&amp;gt; main() File &amp;#34;/home/project/app/manage.py&amp;#34;, line 29, in main execute_from_command_line(sys.argv) File &amp;#34;/usr/local/lib/python3.10/site-packages/django/core/management/__init__.py&amp;#34;, line 446, in execute_from_command_line utility.execute() File &amp;#34;/usr/local/lib/python3.10/site-packages/django/core/management/__init__.py&amp;#34;, line 440, in execute self.fetch_command(subcommand).run_from_argv(self.argv) File &amp;#34;/usr/local/lib/python3.10/site-packages/django/core/management/base.py&amp;#34;, line 402, in run_from_argv self.</description>
    </item>
    
  </channel>
</rss>
